<?xml version="1.0" ?>
<!-- =================================================================================== -->
<!-- |    This document was autogenerated by xacro from mycobot.urdf.xacro             | -->
<!-- |    EDITING THIS FILE BY HAND IS NOT RECOMMENDED                                 | -->
<!-- =================================================================================== -->
<robot name="mycobot">
  <gazebo reference="body_link">
    <mu1>0.5</mu1>
    <mu2>0.5</mu2>
    <kp>100000.0</kp>
    <kd>0</kd>
  </gazebo>
  <gazebo reference="arm1_link">
    <mu1>0.5</mu1>
    <mu2>0.5</mu2>
    <kp>100000.0</kp>
    <kd>0</kd>
  </gazebo>
  <gazebo reference="arm2_link">
    <mu1>0.5</mu1>
    <mu2>0.5</mu2>
    <kp>100000.0</kp>
    <kd>0</kd>
  </gazebo>
  <gazebo reference="arm3_link">
    <mu1>0.5</mu1>
    <mu2>0.5</mu2>
    <kp>100000.0</kp>
    <kd>0</kd>
  </gazebo>
  <gazebo reference="arm4_link">
    <mu1>0.5</mu1>
    <mu2>0.5</mu2>
    <kp>100000.0</kp>
    <kd>0</kd>
  </gazebo>
  <gazebo reference="arm5_link">
    <mu1>0.5</mu1>
    <mu2>0.5</mu2>
    <kp>100000.0</kp>
    <kd>0</kd>
  </gazebo>
  <gazebo reference="arm5_flange">
    <mu1>0.5</mu1>
    <mu2>0.5</mu2>
    <kp>100000.0</kp>
    <kd>0</kd>
  </gazebo>
  <transmission name="arm_trans">
    <type>transmission_interface/SimpleTransmission</type>
    <joint name="arm1_joint">
      <hardwareInterface>hardware_interface/PositionJointInterface</hardwareInterface>
    </joint>
    <actuator name="arm_motor">
      <hardwareInterface>hardware_interface/PositionJointInterface</hardwareInterface>
      <mechanicalReduction>1</mechanicalReduction>
    </actuator>
  </transmission>
  <transmission name="arm_trans">
    <type>transmission_interface/SimpleTransmission</type>
    <joint name="arm2_joint">
      <hardwareInterface>hardware_interface/PositionJointInterface</hardwareInterface>
    </joint>
    <actuator name="arm_motor">
      <hardwareInterface>hardware_interface/PositionJointInterface</hardwareInterface>
      <mechanicalReduction>1</mechanicalReduction>
    </actuator>
  </transmission>
  <transmission name="arm_trans">
    <type>transmission_interface/SimpleTransmission</type>
    <joint name="arm3_joint">
      <hardwareInterface>hardware_interface/PositionJointInterface</hardwareInterface>
    </joint>
    <actuator name="arm_motor">
      <hardwareInterface>hardware_interface/PositionJointInterface</hardwareInterface>
      <mechanicalReduction>1</mechanicalReduction>
    </actuator>
  </transmission>
  <transmission name="arm_trans">
    <type>transmission_interface/SimpleTransmission</type>
    <joint name="arm4_joint">
      <hardwareInterface>hardware_interface/PositionJointInterface</hardwareInterface>
    </joint>
    <actuator name="arm_motor">
      <hardwareInterface>hardware_interface/PositionJointInterface</hardwareInterface>
      <mechanicalReduction>1</mechanicalReduction>
    </actuator>
  </transmission>
  <transmission name="arm_trans">
    <type>transmission_interface/SimpleTransmission</type>
    <joint name="arm5_joint">
      <hardwareInterface>hardware_interface/PositionJointInterface</hardwareInterface>
    </joint>
    <actuator name="arm_motor">
      <hardwareInterface>hardware_interface/PositionJointInterface</hardwareInterface>
      <mechanicalReduction>1</mechanicalReduction>
    </actuator>
  </transmission>
  <transmission name="arm_trans">
    <type>transmission_interface/SimpleTransmission</type>
    <joint name="arm5_flange_joint">
      <hardwareInterface>hardware_interface/PositionJointInterface</hardwareInterface>
    </joint>
    <actuator name="arm_motor">
      <hardwareInterface>hardware_interface/PositionJointInterface</hardwareInterface>
      <mechanicalReduction>1</mechanicalReduction>
    </actuator>
  </transmission>
  <gazebo>
    <plugin filename="libgazebo_ros_control.so" name="gazebo_ros_control">
      <robotNamespace>/mycobot</robotNamespace>
    </plugin>
  </gazebo>
  <!-- Now we can start using the macros included above to define the actual Mycobot -->
  <link name="world"/>
  <joint name="body_joint" type="fixed">
    <origin rpy="0 0 0" xyz="0 0 0"/>
    <!-- transform from parent link to this joint frame -->
    <parent link="world"/>
    <child link="body_link"/>
  </joint>
  <!-- defining the links-->
  <link name="body_link">
    <visual>
      <geometry>
        <mesh filename="/home/jiayin/catkin_ws/src/mycobot_ros/mycobot_description/meshes/arm/body_link.dae"/>
      </geometry>
      <origin rpy=" 0 0 0" xyz="0.0 0 0 "/>
    </visual>
    <collision>
      <geometry>
        <mesh filename="/home/jiayin/catkin_ws/src/mycobot_ros/mycobot_description/meshes/arm/body_link.dae"/>
      </geometry>
      <origin rpy=" 0 0 0" xyz="0.0 0 1e-5"/>
    </collision>
    <inertial>
      <origin rpy="0 0 0" xyz="0.0112 0 0.03742"/>
      <mass value="0.35"/>
      <inertia ixx="3.82e-4" ixy="-1.628e-9" ixz="3.25e-6" iyy="5.09e-4" iyz="-1.66e-9" izz="5.38e-4"/>
    </inertial>
  </link>
  <link name="arm1_link">
    <visual>
      <geometry>
        <mesh filename="/home/jiayin/catkin_ws/src/mycobot_ros/mycobot_description/meshes/arm/arm1_link.dae"/>
      </geometry>
      <origin rpy=" 0 0 -1.5708" xyz="0.0 0 -0.06096 "/>
    </visual>
    <collision>
      <geometry>
        <mesh filename="/home/jiayin/catkin_ws/src/mycobot_ros/mycobot_description/meshes/arm/arm1_link.dae"/>
      </geometry>
      <origin rpy=" 0 0 -1.5708" xyz="0.0 0 -0.06096 "/>
    </collision>
    <inertial>
      <origin rpy="0 0 -1.5708" xyz="0 -0.006642 -0.02617"/>
      <mass value="0.075"/>
      <inertia ixx="5e-5" ixy="0" ixz="0" iyy="5e-5" iyz="0" izz="3e-5"/>
    </inertial>
  </link>
  <link name="arm2_link">
    <visual>
      <geometry>
        <mesh filename="/home/jiayin/catkin_ws/src/mycobot_ros/mycobot_description/meshes/arm/arm2_link.dae"/>
      </geometry>
      <origin rpy=" 0 -1.5708 0" xyz="0.0 0 0.03256 "/>
    </visual>
    <collision>
      <geometry>
        <mesh filename="/home/jiayin/catkin_ws/src/mycobot_ros/mycobot_description/meshes/arm/arm2_link.dae"/>
      </geometry>
      <origin rpy=" 0 -1.5708 0" xyz="0.0 0 0.03256 "/>
    </collision>
    <inertial>
      <origin rpy="0 -1.5708 0" xyz="-0.0543 0 0.058"/>
      <mass value="0.15"/>
      <inertia ixx="2e-4" ixy="0.0" ixz="0.0" iyy="2e-4" iyz="0.0" izz="5e-5"/>
    </inertial>
  </link>
  <link name="arm3_link">
    <visual>
      <geometry>
        <mesh filename="/home/jiayin/catkin_ws/src/mycobot_ros/mycobot_description/meshes/arm/arm3_link.dae"/>
      </geometry>
      <origin rpy=" 0 -1.5708 0" xyz="0.0 0 0.03056 "/>
    </visual>
    <collision>
      <geometry>
        <mesh filename="/home/jiayin/catkin_ws/src/mycobot_ros/mycobot_description/meshes/arm/arm3_link.dae"/>
      </geometry>
      <origin rpy=" 0 -1.5708 0" xyz="0.0 0 0.03056 "/>
    </collision>
    <inertial>
      <origin rpy="0 -1.5708 0" xyz="-0.05 0 0.003"/>
      <mass value="0.15"/>
      <inertia ixx="1.8e-4" ixy="0.0" ixz="0.0" iyy="1.8e-4" iyz="0.0" izz="4e-5"/>
    </inertial>
  </link>
  <link name="arm4_link">
    <visual>
      <geometry>
        <mesh filename="/home/jiayin/catkin_ws/src/mycobot_ros/mycobot_description/meshes/arm/arm4_link.dae"/>
      </geometry>
      <origin rpy=" -1.5708 0 0" xyz="0.0 0 -0.03356 "/>
    </visual>
    <collision>
      <geometry>
        <mesh filename="/home/jiayin/catkin_ws/src/mycobot_ros/mycobot_description/meshes/arm/arm4_link.dae"/>
      </geometry>
      <origin rpy=" -1.5708 0 0" xyz="0.0 0 -0.03356 "/>
    </collision>
    <inertial>
      <origin rpy="-1.5708 0 0" xyz="0 -0.005 -0.005"/>
      <mass value="0.05"/>
      <inertia ixx="1.8e-5" ixy="0.0" ixz="0.0" iyy="1.8e-5" iyz="0.0" izz="1.8e-5"/>
    </inertial>
  </link>
  <link name="arm5_link">
    <visual>
      <geometry>
        <mesh filename="/home/jiayin/catkin_ws/src/mycobot_ros/mycobot_description/meshes/arm/arm5_link.dae"/>
      </geometry>
      <origin rpy=" 0 0 0" xyz="0.0 0 -0.038 "/>
    </visual>
    <collision>
      <geometry>
        <mesh filename="/home/jiayin/catkin_ws/src/mycobot_ros/mycobot_description/meshes/arm/arm5_link.dae"/>
      </geometry>
      <origin rpy=" 0 0 0" xyz="0.0 0 -0.038 "/>
    </collision>
    <inertial>
      <origin rpy="0 0 0" xyz="0 0.0049 -0.005"/>
      <mass value="0.06"/>
      <inertia ixx="1.8e-5" ixy="0.0" ixz="0.0" iyy="1.8e-5" iyz="0.0" izz="1.8e-5"/>
    </inertial>
  </link>
  <link name="arm5_flange">
    <visual>
      <geometry>
        <mesh filename="/home/jiayin/catkin_ws/src/mycobot_ros/mycobot_description/meshes/arm/arm5_flange.dae"/>
      </geometry>
      <origin rpy=" 0 0 0" xyz="0.0 0 -0.012 "/>
    </visual>
    <collision>
      <geometry>
        <mesh filename="/home/jiayin/catkin_ws/src/mycobot_ros/mycobot_description/meshes/arm/arm5_flange.dae"/>
      </geometry>
      <origin rpy=" 0 0 0" xyz="0.0 0 -0.012 "/>
    </collision>
    <inertial>
      <origin rpy="0 0 0" xyz="0 0 -0.004"/>
      <mass value="0.015"/>
      <inertia ixx="1.3e-6" ixy="0.0" ixz="0.0" iyy="1.3e-6" iyz="0.0" izz="2e-6"/>
    </inertial>
  </link>
  <!-- defining the joints -->
  <joint name="arm1_joint" type="revolute">
    <axis xyz="0 0 1"/>
    <limit effort="1000.0" lower="-2.88" upper="2.88" velocity="0.2"/>
    <dynamics damping="0.01" friction="0.01"/>
    <parent link="body_link"/>
    <child link="arm1_link"/>
    <origin rpy="0 0 0" xyz="0 0 0.13156"/>
  </joint>
  <joint name="arm2_joint" type="revolute">
    <axis xyz="0 0 1"/>
    <limit effort="1000.0" lower="-2.88" upper="2.88" velocity="0.2"/>
    <dynamics damping="0.01" friction="0.01"/>
    <parent link="arm1_link"/>
    <child link="arm2_link"/>
    <origin rpy="0 1.5708 -1.5708" xyz="0 0 0"/>
  </joint>
  <joint name="arm3_joint" type="revolute">
    <axis xyz=" 0 0 1"/>
    <limit effort="1000.0" lower="-2.88" upper="2.88" velocity="0.2"/>
    <dynamics damping="0.01" friction="0.01"/>
    <parent link="arm2_link"/>
    <child link="arm3_link"/>
    <origin rpy="0 0 0" xyz="  -0.1104 0 0   "/>
  </joint>
  <joint name="arm4_joint" type="revolute">
    <axis xyz=" 0 0 1"/>
    <limit effort="1000.0" lower="-2.88" upper="2.88" velocity="0.2"/>
    <dynamics damping="0.01" friction="0.01"/>
    <parent link="arm3_link"/>
    <child link="arm4_link"/>
    <origin rpy="0 0 -1.5708" xyz="-0.096 0 0.06462"/>
  </joint>
  <joint name="arm5_joint" type="revolute">
    <axis xyz="0 0 1"/>
    <limit effort="1000.0" lower="-2.88" upper="2.88" velocity="0.2"/>
    <dynamics damping="0.01" friction="0.01"/>
    <parent link="arm4_link"/>
    <child link="arm5_link"/>
    <origin rpy="1.5708 -1.5708 0" xyz="0 -0.07318 0"/>
  </joint>
  <joint name="arm5_flange_joint" type="revolute">
    <axis xyz="0 0 1"/>
    <limit effort="1000.0" lower="-3.05" upper="3.05" velocity="0.2"/>
    <dynamics damping="0.01" friction="0.01"/>
    <parent link="arm5_link"/>
    <child link="arm5_flange"/>
    <origin rpy="-1.5708 0 0" xyz="0 0.0456 0"/>
  </joint>
</robot>
