<?xml version="1.0" encoding="utf-8"?>
<!-- This URDF was automatically created by SolidWorks to URDF Exporter! Originally created by Stephen Brawner (brawner@gmail.com) 
     Commit Version: 1.6.0-4-g7f85cfe  Build Version: 1.6.7995.38578
     For more information, please see http://wiki.ros.org/sw_urdf_exporter -->
<robot
  name="mycobot_gripper_description">
  <link
    name="base_link">
    <inertial>
      <origin
        xyz="0 -0.018162 0"
        rpy="1.5708 0 0" />
      <mass
        value="0.03237" />
      <inertia
        ixx="7.9803E-06"
        ixy="-3.7162E-08"
        ixz="4.3435E-07"
        iyy="1.0337E-05"
        iyz="3.3485E-07"
        izz="1.5321E-05" />
    </inertial>
    <visual>
      <origin
        xyz="0 0 0"
        rpy="0 0 0" />
      <geometry>
        <mesh
          filename="package://mycobot_gripper_description/meshes/base_link.STL" />
      </geometry>
      <material
        name="">
        <color
          rgba="0.79216 0.81961 0.93333 1" />
      </material>
    </visual>
    <collision>
      <origin
        xyz="0 0 0"
        rpy="0 0 0" />
      <geometry>
        <mesh
          filename="package://mycobot_gripper_description/meshes/base_link.STL" />
      </geometry>
    </collision>
  </link>
  <link
    name="left_inner_knuckle_link">
    <inertial>
      <origin
        xyz="-0.013688 0.0077832 0.01"
        rpy="0 0 0" />
      <mass
        value="0.0027253" />
      <inertia
        ixx="2.3883E-07"
        ixy="1.3724E-07"
        ixz="5.0465E-14"
        iyy="4.0216E-07"
        iyz="-1.3375E-14"
        izz="3.5516E-07" />
    </inertial>
    <visual>
      <origin
        xyz="0 0 0"
        rpy="0 0 0" />
      <geometry>
        <mesh
          filename="package://mycobot_gripper_description/meshes/left_inner_knuckle_link.STL" />
      </geometry>
      <material
        name="">
        <color
          rgba="0.79216 0.81961 0.93333 1" />
      </material>
    </visual>
    <collision>
      <origin
        xyz="0 0 0"
        rpy="0 0 0" />
      <geometry>
        <mesh
          filename="package://mycobot_gripper_description/meshes/left_inner_knuckle_link.STL" />
      </geometry>
    </collision>
  </link>
  <joint
    name="left_inner_base_knuckle_joint"
    type="continuous">
    <origin
      xyz="-0.006 0.0062 0.01931"
      rpy="1.5708 0 0" />
    <parent
      link="base_link" />
    <child
      link="left_inner_knuckle_link" />
    <axis
      xyz="0 0 1" />
    <mimic
      joint="left_outer_base_knuckle_joint"
      multiplier="1"
      offset="0" />
  </joint>
  <link
    name="left_finger_link">
    <inertial>
      <origin
        xyz="-0.011258 -0.00023581 0.005"
        rpy="0 0 0" />
      <mass
        value="0.0069464" />
      <inertia
        ixx="3.0023E-07"
        ixy="1.5317E-07"
        ixz="2.0426E-16"
        iyy="1.5826E-06"
        iyz="-6.683E-17"
        izz="1.4568E-06" />
    </inertial>
    <visual>
      <origin
        xyz="0 0 0"
        rpy="0 0 0" />
      <geometry>
        <mesh
          filename="package://mycobot_gripper_description/meshes/left_finger_link.STL" />
      </geometry>
      <material
        name="">
        <color
          rgba="0.79216 0.81961 0.93333 1" />
      </material>
    </visual>
    <collision>
      <origin
        xyz="0 0 0"
        rpy="0 0 0" />
      <geometry>
        <mesh
          filename="package://mycobot_gripper_description/meshes/left_finger_link.STL" />
      </geometry>
    </collision>
  </link>
  <joint
    name="left_inner_knuckle_finger_joint"
    type="continuous">
    <origin
      xyz="-0.026961 0.01533 0.015"
      rpy="3.1416 0 -1.8908" />
    <parent
      link="left_inner_knuckle_link" />
    <child
      link="left_finger_link" />
    <axis
      xyz="0 0 -1" />
    <mimic
      joint="left_outer_base_knuckle_joint"
      multiplier="-1"
      offset="0" />
  </joint>
  <link
    name="left_outer_knuckle_link">
    <inertial>
      <origin
        xyz="0.0024724 0.0012069 -0.0061758"
        rpy="0 0 0" />
      <mass
        value="0.0031761" />
      <inertia
        ixx="5.5821E-07"
        ixy="-8.1055E-11"
        ixz="4.4412E-10"
        iyy="4.2052E-07"
        iyz="7.9939E-08"
        izz="1.5004E-07" />
    </inertial>
    <visual>
      <origin
        xyz="0 0 0"
        rpy="0 0 0" />
      <geometry>
        <mesh
          filename="package://mycobot_gripper_description/meshes/left_outer_knuckle_link.STL" />
      </geometry>
      <material
        name="">
        <color
          rgba="0.79216 0.81961 0.93333 1" />
      </material>
    </visual>
    <collision>
      <origin
        xyz="0 0 0"
        rpy="0 0 0" />
      <geometry>
        <mesh
          filename="package://mycobot_gripper_description/meshes/left_outer_knuckle_link.STL" />
      </geometry>
    </collision>
  </link>
  <joint
    name="left_outer_base_knuckle_joint"
    type="revolute">
    <origin
      xyz="-0.01325 -0.0138 -0.00252"
      rpy="1.839 0 1.5708" />
    <parent
      link="base_link" />
    <child
      link="left_outer_knuckle_link" />
    <axis
      xyz="-1 0 0" />
    <limit
      lower="-0.75"
      upper="0.2"
      effort="100"
      velocity="2" />
  </joint>
  <link
    name="right_inner_knuckle_link">
    <inertial>
      <origin
        xyz="0.013579 0.007972 0.0099999"
        rpy="0 0 0" />
      <mass
        value="0.0027253" />
      <inertia
        ixx="2.4267E-07"
        ixy="-1.3945E-07"
        ixz="5.0275E-14"
        iyy="3.9832E-07"
        iyz="1.4073E-14"
        izz="3.5516E-07" />
    </inertial>
    <visual>
      <origin
        xyz="0 0 0"
        rpy="0 0 0" />
      <geometry>
        <mesh
          filename="package://mycobot_gripper_description/meshes/right_inner_knuckle_link.STL" />
      </geometry>
      <material
        name="">
        <color
          rgba="0.79216 0.81961 0.93333 1" />
      </material>
    </visual>
    <collision>
      <origin
        xyz="0 0 0"
        rpy="0 0 0" />
      <geometry>
        <mesh
          filename="package://mycobot_gripper_description/meshes/right_inner_knuckle_link.STL" />
      </geometry>
    </collision>
  </link>
  <joint
    name="right_inner_base_knuckle_joint"
    type="continuous">
    <origin
      xyz="0.005 0.0062 0.01931"
      rpy="1.5708 0 0" />
    <parent
      link="base_link" />
    <child
      link="right_inner_knuckle_link" />
    <axis
      xyz="0 0 1" />
    <mimic
      joint="left_outer_base_knuckle_joint"
      multiplier="-1"
      offset="0" />
  </joint>
  <link
    name="right_finger_link">
    <inertial>
      <origin
        xyz="-0.011258 -0.00023581 0.005"
        rpy="0 0 0" />
      <mass
        value="0.0069464" />
      <inertia
        ixx="3.0023E-07"
        ixy="1.5317E-07"
        ixz="2.0426E-16"
        iyy="1.5826E-06"
        iyz="-6.683E-17"
        izz="1.4568E-06" />
    </inertial>
    <visual>
      <origin
        xyz="0 0 0"
        rpy="0 0 0" />
      <geometry>
        <mesh
          filename="package://mycobot_gripper_description/meshes/right_finger_link.STL" />
      </geometry>
      <material
        name="">
        <color
          rgba="0.79216 0.81961 0.93333 1" />
      </material>
    </visual>
    <collision>
      <origin
        xyz="0 0 0"
        rpy="0 0 0" />
      <geometry>
        <mesh
          filename="package://mycobot_gripper_description/meshes/right_finger_link.STL" />
      </geometry>
    </collision>
  </link>
  <joint
    name="right_inner_knuckle_finger_joint"
    type="continuous">
    <origin
      xyz="0.026746 0.015702 0.005"
      rpy="0 0 -1.2508" />
    <parent
      link="right_inner_knuckle_link" />
    <child
      link="right_finger_link" />
    <axis
      xyz="0 0 1" />
    <mimic
      joint="left_outer_base_knuckle_joint"
      multiplier="1"
      offset="0" />
  </joint>
  <link
    name="right_outer_knuckle_link">
    <inertial>
      <origin
        xyz="0.0026671 -0.003562 0.0056204"
        rpy="0 0 0" />
      <mass
        value="0.0030687" />
      <inertia
        ixx="5.4543E-07"
        ixy="-1.7697E-09"
        ixz="2.7991E-09"
        iyy="3.3169E-07"
        iyz="1.4798E-07"
        izz="2.2484E-07" />
    </inertial>
    <visual>
      <origin
        xyz="0 0 0"
        rpy="0 0 0" />
      <geometry>
        <mesh
          filename="package://mycobot_gripper_description/meshes/right_outer_knuckle_link.STL" />
      </geometry>
      <material
        name="">
        <color
          rgba="0.79216 0.81961 0.93333 1" />
      </material>
    </visual>
    <collision>
      <origin
        xyz="0 0 0"
        rpy="0 0 0" />
      <geometry>
        <mesh
          filename="package://mycobot_gripper_description/meshes/right_outer_knuckle_link.STL" />
      </geometry>
    </collision>
  </link>
  <joint
    name="right_outer_base_knuckle_link"
    type="continuous">
    <origin
      xyz="0.01225 -0.0088 -0.00252"
      rpy="-1.6401 0 -1.5708" />
    <parent
      link="base_link" />
    <child
      link="right_outer_knuckle_link" />
    <axis
      xyz="1 0 0" />
    <mimic
      joint="left_outer_base_knuckle_joint"
      multiplier="-1"
      offset="0" />
  </joint>
</robot>
