<?xml version="1.0" ?>
<!-- =================================================================================== -->
<!-- |    This document was autogenerated by xacro from /home/jiayin/simulation_ws/src/mycobot_description/robots/mycobot_with_gripper_camera.urdf.xacro | -->
<!-- |    EDITING THIS FILE BY HAND IS NOT RECOMMENDED                                 | -->
<!-- =================================================================================== -->
<robot name="mycobot">
    <gazebo reference="body_link">
        <mu1>0.5</mu1>
        <mu2>0.5</mu2>
        <kp>100000.0</kp>
        <kd>0</kd>
        <plugin name="gazebo_ros_control">
            <robotNamespace>/</robotNamespace>
        </plugin>
    </gazebo>
    <gazebo reference="arm1_link">
        <mu1>0.5</mu1>
        <mu2>0.5</mu2>
        <kp>100000.0</kp>
        <kd>0</kd>
    </gazebo>
    <gazebo reference="arm2_link">
        <mu1>0.5</mu1>
        <mu2>0.5</mu2>
        <kp>100000.0</kp>
        <kd>0</kd>
    </gazebo>
    <gazebo reference="arm3_link">
        <mu1>0.5</mu1>
        <mu2>0.5</mu2>
        <kp>100000.0</kp>
        <kd>0</kd>
    </gazebo>
    <gazebo reference="arm4_link">
        <mu1>0.5</mu1>
        <mu2>0.5</mu2>
        <kp>100000.0</kp>
        <kd>0</kd>
    </gazebo>
    <gazebo reference="arm5_link">
        <mu1>0.5</mu1>
        <mu2>0.5</mu2>
        <kp>100000.0</kp>
        <kd>0</kd>
    </gazebo>
    <gazebo reference="arm5_flange">
        <mu1>0.5</mu1>
        <mu2>0.5</mu2>
        <kp>100000.0</kp>
        <kd>0</kd>
    </gazebo>
    <transmission name="arm_trans">
        <type>transmission_interface/SimpleTransmission</type>
        <joint name="arm1_joint">
            <hardwareInterface>hardware_interface/PositionJointInterface</hardwareInterface>
        </joint>
        <actuator name="arm_motor">
            <hardwareInterface>hardware_interface/PositionJointInterface</hardwareInterface>
            <mechanicalReduction>1</mechanicalReduction>
        </actuator>
    </transmission>
    <transmission name="arm_trans">
        <type>transmission_interface/SimpleTransmission</type>
        <joint name="arm2_joint">
            <hardwareInterface>hardware_interface/PositionJointInterface</hardwareInterface>
        </joint>
        <actuator name="arm_motor">
            <hardwareInterface>hardware_interface/PositionJointInterface</hardwareInterface>
            <mechanicalReduction>1</mechanicalReduction>
        </actuator>
    </transmission>
    <transmission name="arm_trans">
        <type>transmission_interface/SimpleTransmission</type>
        <joint name="arm3_joint">
            <hardwareInterface>hardware_interface/PositionJointInterface</hardwareInterface>
        </joint>
        <actuator name="arm_motor">
            <hardwareInterface>hardware_interface/PositionJointInterface</hardwareInterface>
            <mechanicalReduction>1</mechanicalReduction>
        </actuator>
    </transmission>
    <transmission name="arm_trans">
        <type>transmission_interface/SimpleTransmission</type>
        <joint name="arm4_joint">
            <hardwareInterface>hardware_interface/PositionJointInterface</hardwareInterface>
        </joint>
        <actuator name="arm_motor">
            <hardwareInterface>hardware_interface/PositionJointInterface</hardwareInterface>
            <mechanicalReduction>1</mechanicalReduction>
        </actuator>
    </transmission>
    <transmission name="arm_trans">
        <type>transmission_interface/SimpleTransmission</type>
        <joint name="arm5_joint">
            <hardwareInterface>hardware_interface/PositionJointInterface</hardwareInterface>
        </joint>
        <actuator name="arm_motor">
            <hardwareInterface>hardware_interface/PositionJointInterface</hardwareInterface>
            <mechanicalReduction>1</mechanicalReduction>
        </actuator>
    </transmission>
    <transmission name="arm_trans">
        <type>transmission_interface/SimpleTransmission</type>
        <joint name="arm5_flange_joint">
            <hardwareInterface>hardware_interface/PositionJointInterface</hardwareInterface>
        </joint>
        <actuator name="arm_motor">
            <hardwareInterface>hardware_interface/PositionJointInterface</hardwareInterface>
            <mechanicalReduction>1</mechanicalReduction>
        </actuator>
    </transmission>
    <gazebo>
        <plugin filename="libroboticsgroup_gazebo_mimic_joint_plugin.so" name="left_inner_base_knuckle_jointmimic_joint_plugin">
            <joint>left_outer_base_knuckle_joint</joint>
            <mimicJoint>left_inner_base_knuckle_joint</mimicJoint>
            <!-- if set to true, PID parameters from "/gazebo_ros_control/pid_gains/${mimic_joint}" are loaded -->
            <hasPID />
            <multiplier>1.0</multiplier>
            <offset>0</offset>
            <sensitiveness>0.0</sensitiveness>
            <!-- if absolute difference between setpoint and process value is below this threshold, do nothing; 0.0 = disable [rad] -->
            <maxEffort>10.0</maxEffort>
        </plugin>
    </gazebo>
    <gazebo>
        <plugin filename="libroboticsgroup_gazebo_mimic_joint_plugin.so" name="left_inner_knuckle_finger_jointmimic_joint_plugin">
            <joint>left_outer_base_knuckle_joint</joint>
            <mimicJoint>left_inner_knuckle_finger_joint</mimicJoint>
            <!-- if set to true, PID parameters from "/gazebo_ros_control/pid_gains/${mimic_joint}" are loaded -->
            <hasPID />
            <multiplier>-1.0</multiplier>
            <offset>0</offset>
            <sensitiveness>0.0</sensitiveness>
            <!-- if absolute difference between setpoint and process value is below this threshold, do nothing; 0.0 = disable [rad] -->
            <maxEffort>10.0</maxEffort>
        </plugin>
    </gazebo>
    <gazebo>
        <plugin filename="libroboticsgroup_gazebo_mimic_joint_plugin.so" name="right_inner_base_knuckle_jointmimic_joint_plugin">
            <joint>left_outer_base_knuckle_joint</joint>
            <mimicJoint>right_inner_base_knuckle_joint</mimicJoint>
            <!-- if set to true, PID parameters from "/gazebo_ros_control/pid_gains/${mimic_joint}" are loaded -->
            <hasPID />
            <multiplier>-1.0</multiplier>
            <offset>0</offset>
            <sensitiveness>0.0</sensitiveness>
            <!-- if absolute difference between setpoint and process value is below this threshold, do nothing; 0.0 = disable [rad] -->
            <maxEffort>10.0</maxEffort>
        </plugin>
    </gazebo>
    <gazebo>
        <plugin filename="libroboticsgroup_gazebo_mimic_joint_plugin.so" name="right_inner_knuckle_finger_jointmimic_joint_plugin">
            <joint>left_outer_base_knuckle_joint</joint>
            <mimicJoint>right_inner_knuckle_finger_joint</mimicJoint>
            <!-- if set to true, PID parameters from "/gazebo_ros_control/pid_gains/${mimic_joint}" are loaded -->
            <hasPID />
            <multiplier>1.0</multiplier>
            <offset>0</offset>
            <sensitiveness>0.0</sensitiveness>
            <!-- if absolute difference between setpoint and process value is below this threshold, do nothing; 0.0 = disable [rad] -->
            <maxEffort>10.0</maxEffort>
        </plugin>
    </gazebo>
    <gazebo>
        <plugin filename="libroboticsgroup_gazebo_mimic_joint_plugin.so" name="right_outer_base_knuckle_jointmimic_joint_plugin">
            <joint>left_outer_base_knuckle_joint</joint>
            <mimicJoint>right_outer_base_knuckle_joint</mimicJoint>
            <!-- if set to true, PID parameters from "/gazebo_ros_control/pid_gains/${mimic_joint}" are loaded -->
            <hasPID />
            <multiplier>-1.0</multiplier>
            <offset>0</offset>
            <sensitiveness>0.0</sensitiveness>
            <!-- if absolute difference between setpoint and process value is below this threshold, do nothing; 0.0 = disable [rad] -->
            <maxEffort>10.0</maxEffort>
        </plugin>
    </gazebo>
    <transmission name="gripper_trans">
        <type>transmission_interface/SimpleTransmission</type>
        <joint name="left_outer_base_knuckle_joint">
            <hardwareInterface>hardware_interface/PositionJointInterface</hardwareInterface>
        </joint>
        <actuator name="gripper_motor">
            <hardwareInterface>hardware_interface/PositionJointInterface</hardwareInterface>
            <mechanicalReduction>1</mechanicalReduction>
        </actuator>
    </transmission>
    <gazebo>
        <plugin filename="libgazebo_ros_control.so" name="gazebo_ros_control">
            <robotNamespace>/mycobot</robotNamespace>
        </plugin>
    </gazebo>
    <!-- Now we can start using the macros included above to define the actual Mycobot -->
    <link name="world" />
    <joint name="body_joint" type="fixed">
        <origin rpy="0 0 0" xyz="0 0 0" />
        <!-- transform from parent link to this joint frame -->
        <parent link="world" />
        <child link="body_link" />
    </joint>
    <!-- defining the links-->
    <link name="body_link">
        <visual>
            <geometry>
                <mesh filename="package://mycobot_description/meshes/arm/body_link.dae" />
            </geometry>
            <origin rpy=" 0 0 0" xyz="0.0 0 0 " />
        </visual>
        <collision>
            <geometry>
                <mesh filename="package://mycobot_description/meshes/arm/body_link.dae" />
            </geometry>
            <origin rpy=" 0 0 0" xyz="0.0 0 1e-5" />
        </collision>
        <inertial>
            <origin rpy="0 0 0" xyz="0.0112 0 0.03742" />
            <mass value="0.35" />
            <inertia ixx="3.82e-4" ixy="-1.628e-9" ixz="3.25e-6" iyy="5.09e-4" iyz="-1.66e-9" izz="5.38e-4" />
        </inertial>
    </link>
    <link name="arm1_link">
        <visual>
            <geometry>
                <mesh filename="package://mycobot_description/meshes/arm/arm1_link.dae" />
            </geometry>
            <origin rpy=" 0 0 -1.5708" xyz="0.0 0 -0.06096 " />
        </visual>
        <collision>
            <geometry>
                <mesh filename="package://mycobot_description/meshes/arm/arm1_link.dae" />
            </geometry>
            <origin rpy=" 0 0 -1.5708" xyz="0.0 0 -0.06096 " />
        </collision>
        <inertial>
            <origin rpy="0 0 -1.5708" xyz="0 -0.006642 -0.02617" />
            <mass value="0.075" />
            <inertia ixx="5e-5" ixy="0" ixz="0" iyy="5e-5" iyz="0" izz="3e-5" />
        </inertial>
    </link>
    <link name="arm2_link">
        <visual>
            <geometry>
                <mesh filename="package://mycobot_description/meshes/arm/arm2_link.dae" />
            </geometry>
            <origin rpy=" 0 -1.5708 0" xyz="0.0 0 0.03256 " />
        </visual>
        <collision>
            <geometry>
                <mesh filename="package://mycobot_description/meshes/arm/arm2_link.dae" />
            </geometry>
            <origin rpy=" 0 -1.5708 0" xyz="0.0 0 0.03256 " />
        </collision>
        <inertial>
            <origin rpy="0 -1.5708 0" xyz="-0.0543 0 0.058" />
            <mass value="0.15" />
            <inertia ixx="2e-4" ixy="0.0" ixz="0.0" iyy="2e-4" iyz="0.0" izz="5e-5" />
        </inertial>
    </link>
    <link name="arm3_link">
        <visual>
            <geometry>
                <mesh filename="package://mycobot_description/meshes/arm/arm3_link.dae" />
            </geometry>
            <origin rpy=" 0 -1.5708 0" xyz="0.0 0 0.03056 " />
        </visual>
        <collision>
            <geometry>
                <mesh filename="package://mycobot_description/meshes/arm/arm3_link.dae" />
            </geometry>
            <origin rpy=" 0 -1.5708 0" xyz="0.0 0 0.03056 " />
        </collision>
        <inertial>
            <origin rpy="0 -1.5708 0" xyz="-0.05 0 0.003" />
            <mass value="0.15" />
            <inertia ixx="1.8e-4" ixy="0.0" ixz="0.0" iyy="1.8e-4" iyz="0.0" izz="4e-5" />
        </inertial>
    </link>
    <link name="arm4_link">
        <visual>
            <geometry>
                <mesh filename="package://mycobot_description/meshes/arm/arm4_link.dae" />
            </geometry>
            <origin rpy=" -1.5708 0 0" xyz="0.0 0 -0.03356 " />
        </visual>
        <collision>
            <geometry>
                <mesh filename="package://mycobot_description/meshes/arm/arm4_link.dae" />
            </geometry>
            <origin rpy=" -1.5708 0 0" xyz="0.0 0 -0.03356 " />
        </collision>
        <inertial>
            <origin rpy="-1.5708 0 0" xyz="0 -0.005 -0.005" />
            <mass value="0.05" />
            <inertia ixx="1.8e-5" ixy="0.0" ixz="0.0" iyy="1.8e-5" iyz="0.0" izz="1.8e-5" />
        </inertial>
    </link>
    <link name="arm5_link">
        <visual>
            <geometry>
                <mesh filename="package://mycobot_description/meshes/arm/arm5_link.dae" />
            </geometry>
            <origin rpy=" 0 0 0" xyz="0.0 0 -0.038 " />
        </visual>
        <collision>
            <geometry>
                <mesh filename="package://mycobot_description/meshes/arm/arm5_link.dae" />
            </geometry>
            <origin rpy=" 0 0 0" xyz="0.0 0 -0.038 " />
        </collision>
        <inertial>
            <origin rpy="0 0 0" xyz="0 0.0049 -0.005" />
            <mass value="0.06" />
            <inertia ixx="1.8e-5" ixy="0.0" ixz="0.0" iyy="1.8e-5" iyz="0.0" izz="1.8e-5" />
        </inertial>
    </link>
    <link name="arm5_flange">
        <visual>
            <geometry>
                <mesh filename="package://mycobot_description/meshes/arm/arm5_flange.dae" />
            </geometry>
            <origin rpy=" 0 0 0" xyz="0.0 0 -0.012 " />
        </visual>
        <collision>
            <geometry>
                <mesh filename="package://mycobot_description/meshes/arm/arm5_flange.dae" />
            </geometry>
            <origin rpy=" 0 0 0" xyz="0.0 0 -0.012 " />
        </collision>
        <inertial>
            <origin rpy="0 0 0" xyz="0 0 -0.004" />
            <mass value="0.015" />
            <inertia ixx="1.3e-6" ixy="0.0" ixz="0.0" iyy="1.3e-6" iyz="0.0" izz="2e-6" />
        </inertial>
    </link>
    <!-- defining the joints -->
    <joint name="arm1_joint" type="revolute">
        <axis xyz="0 0 1" />
        <limit effort="1000.0" lower="-2.88" upper="2.88" velocity="0.2" />
        <dynamics damping="0.01" friction="0.01" />
        <parent link="body_link" />
        <child link="arm1_link" />
        <origin rpy="0 0 0" xyz="0 0 0.13156" />
    </joint>
    <joint name="arm2_joint" type="revolute">
        <axis xyz="0 0 1" />
        <limit effort="1000.0" lower="-2.88" upper="2.88" velocity="0.2" />
        <dynamics damping="0.01" friction="0.01" />
        <parent link="arm1_link" />
        <child link="arm2_link" />
        <origin rpy="0 1.5708 -1.5708" xyz="0 0 0" />
    </joint>
    <joint name="arm3_joint" type="revolute">
        <axis xyz=" 0 0 1" />
        <limit effort="1000.0" lower="-2.88" upper="2.88" velocity="0.2" />
        <dynamics damping="0.01" friction="0.01" />
        <parent link="arm2_link" />
        <child link="arm3_link" />
        <origin rpy="0 0 0" xyz="  -0.1104 0 0   " />
    </joint>
    <joint name="arm4_joint" type="revolute">
        <axis xyz=" 0 0 1" />
        <limit effort="1000.0" lower="-2.88" upper="2.88" velocity="0.2" />
        <dynamics damping="0.01" friction="0.01" />
        <parent link="arm3_link" />
        <child link="arm4_link" />
        <origin rpy="0 0 -1.5708" xyz="-0.096 0 0.06462" />
    </joint>
    <joint name="arm5_joint" type="revolute">
        <axis xyz="0 0 1" />
        <limit effort="1000.0" lower="-2.88" upper="2.88" velocity="0.2" />
        <dynamics damping="0.01" friction="0.01" />
        <parent link="arm4_link" />
        <child link="arm5_link" />
        <origin rpy="1.5708 -1.5708 0" xyz="0 -0.07318 0" />
    </joint>
    <joint name="arm5_flange_joint" type="revolute">
        <axis xyz="0 0 1" />
        <limit effort="1000.0" lower="-3.05" upper="3.05" velocity="0.2" />
        <dynamics damping="0.01" friction="0.01" />
        <parent link="arm5_link" />
        <child link="arm5_flange" />
        <origin rpy="-1.5708 0 0" xyz="0 0.0456 0" />
    </joint>
    <joint name="gripper_base_joint" type="fixed">
        <origin rpy="0 0 0" xyz="0 0.01385 0.03432" />
        <!-- transform from parent link to this joint frame -->
        <parent link="arm5_flange" />
        <child link="gripper_base_link" />
    </joint>
    <!-- defining the base link -->
    <link name="gripper_base_link">
        <inertial>
            <origin rpy="1.5708 0 0" xyz="0 -0.018162 0" />
            <mass value="0.03237" />
            <inertia ixx="7.9803E-06" ixy="-3.7162E-08" ixz="4.3435E-07" iyy="1.0337E-05" iyz="3.3485E-07" izz="1.5321E-05" />
        </inertial>
        <visual>
            <origin rpy="0 0 0" xyz="0 0 0" />
            <geometry>
                <mesh filename="package://mycobot_description/meshes/gripper/base_link.STL" />
            </geometry>
            <material name="">
                <color rgba="0.79216 0.81961 0.93333 1" />
            </material>
        </visual>
        <collision>
            <origin rpy="0 0 0" xyz="0 0 0" />
            <geometry>
                <mesh filename="package://mycobot_description/meshes/gripper/base_link.STL" />
            </geometry>
        </collision>
    </link>
    <!-- defining the left_inner_knuckle_link -->
    <link name="left_inner_knuckle_link">
        <inertial>
            <origin rpy="0 0 0" xyz="-0.013688 0.0077832 0.01" />
            <mass value="0.0027253" />
            <inertia ixx="2.3883E-07" ixy="1.3724E-07" ixz="5.0465E-14" iyy="4.0216E-07" iyz="-1.3375E-14" izz="3.5516E-07" />
        </inertial>
        <visual>
            <origin rpy="0 0 0" xyz="0 0 0" />
            <geometry>
                <mesh filename="package://mycobot_description/meshes/gripper/left_inner_knuckle_link.STL" />
            </geometry>
            <material name="">
                <color rgba="0.79216 0.81961 0.93333 1" />
            </material>
        </visual>
        <collision>
            <origin rpy="0 0 0" xyz="0 0 0" />
            <geometry>
                <mesh filename="package://mycobot_description/meshes/gripper/left_inner_knuckle_link.STL" />
            </geometry>
        </collision>
    </link>
    <!-- defining the left_inner_base_knuckle_joint -->
    <joint name="left_inner_base_knuckle_joint" type="continuous">
        <origin rpy="1.5708 0 0" xyz="-0.006 0.0062 0.01931" />
        <parent link="gripper_base_link" />
        <child link="left_inner_knuckle_link" />
        <axis xyz="0 0 1" />
        <mimic joint="left_outer_base_knuckle_joint" multiplier="1" offset="0" />
    </joint>
    <!-- defining the left_finger_link -->
    <link name="left_finger_link">
        <inertial>
            <origin rpy="0 0 0" xyz="-0.011258 -0.00023581 0.005" />
            <mass value="0.0069464" />
            <inertia ixx="3.0023E-07" ixy="1.5317E-07" ixz="2.0426E-16" iyy="1.5826E-06" iyz="-6.683E-17" izz="1.4568E-06" />
        </inertial>
        <visual>
            <origin rpy="0 0 0" xyz="0 0 0" />
            <geometry>
                <mesh filename="package://mycobot_description/meshes/gripper/left_finger_link.STL" />
            </geometry>
            <material name="">
                <color rgba="0.79216 0.81961 0.93333 1" />
            </material>
        </visual>
        <collision>
            <origin rpy="0 0 0" xyz="0 0 0" />
            <geometry>
                <mesh filename="package://mycobot_description/meshes/gripper/left_finger_link.STL" />
            </geometry>
        </collision>
    </link>
    <!-- define the left_inner_knuckle_finger_joint -->
    <joint name="left_inner_knuckle_finger_joint" type="continuous">
        <origin rpy="3.1416 0 -1.8908" xyz="-0.026961 0.01533 0.015" />
        <parent link="left_inner_knuckle_link" />
        <child link="left_finger_link" />
        <axis xyz="0 0 -1" />
        <mimic joint="left_outer_base_knuckle_joint" multiplier="-1" offset="0" />
    </joint>
    <!-- define the left_outer_knuckle_link -->
    <link name="left_outer_knuckle_link">
        <inertial>
            <origin rpy="0 0 0" xyz="0.0024724 0.0012069 -0.0061758" />
            <mass value="0.0031761" />
            <inertia ixx="5.5821E-07" ixy="-8.1055E-11" ixz="4.4412E-10" iyy="4.2052E-07" iyz="7.9939E-08" izz="1.5004E-07" />
        </inertial>
        <visual>
            <origin rpy="0 0 0" xyz="0 0 0" />
            <geometry>
                <mesh filename="package://mycobot_description/meshes/gripper/left_outer_knuckle_link.STL" />
            </geometry>
            <material name="">
                <color rgba="0.79216 0.81961 0.93333 1" />
            </material>
        </visual>
        <collision>
            <origin rpy="0 0 0" xyz="0 0 0" />
            <geometry>
                <mesh filename="package://mycobot_description/meshes/gripper/left_outer_knuckle_link.STL" />
            </geometry>
        </collision>
    </link>
    <!-- define the left_outer_base_knuckle_joint -->
    <joint name="left_outer_base_knuckle_joint" type="revolute">
        <origin rpy="1.839 0 1.5708" xyz="-0.01325 -0.0138 -0.00252" />
        <parent link="gripper_base_link" />
        <child link="left_outer_knuckle_link" />
        <axis xyz="-1 0 0" />
        <limit effort="10" lower="-0.75" upper="0.2" velocity="0.05" />
    </joint>
    <!-- define the right_inner_knuckle_link -->
    <link name="right_inner_knuckle_link">
        <inertial>
            <origin rpy="0 0 0" xyz="0.013579 0.007972 0.0099999" />
            <mass value="0.0027253" />
            <inertia ixx="2.4267E-07" ixy="-1.3945E-07" ixz="5.0275E-14" iyy="3.9832E-07" iyz="1.4073E-14" izz="3.5516E-07" />
        </inertial>
        <visual>
            <origin rpy="0 0 0" xyz="0 0 0" />
            <geometry>
                <mesh filename="package://mycobot_description/meshes/gripper/right_inner_knuckle_link.STL" />
            </geometry>
            <material name="">
                <color rgba="0.79216 0.81961 0.93333 1" />
            </material>
        </visual>
        <collision>
            <origin rpy="0 0 0" xyz="0 0 0" />
            <geometry>
                <mesh filename="package://mycobot_description/meshes/gripper/right_inner_knuckle_link.STL" />
            </geometry>
        </collision>
    </link>
    <!-- define right_inner_base_knuckle_joint -->
    <joint name="right_inner_base_knuckle_joint" type="continuous">
        <origin rpy="1.5708 0 0" xyz="0.005 0.0062 0.01931" />
        <parent link="gripper_base_link" />
        <child link="right_inner_knuckle_link" />
        <axis xyz="0 0 1" />
        <mimic joint="left_outer_base_knuckle_joint" multiplier="-1" offset="0" />
    </joint>
    <!-- define right_finger_link -->
    <link name="right_finger_link">
        <inertial>
            <origin rpy="0 0 0" xyz="-0.011258 -0.00023581 0.005" />
            <mass value="0.0069464" />
            <inertia ixx="3.0023E-07" ixy="1.5317E-07" ixz="2.0426E-16" iyy="1.5826E-06" iyz="-6.683E-17" izz="1.4568E-06" />
        </inertial>
        <visual>
            <origin rpy="0 0 0" xyz="0 0 0" />
            <geometry>
                <mesh filename="package://mycobot_description/meshes/gripper/right_finger_link.STL" />
            </geometry>
            <material name="">
                <color rgba="0.79216 0.81961 0.93333 1" />
            </material>
        </visual>
        <collision>
            <origin rpy="0 0 0" xyz="0 0 0" />
            <geometry>
                <mesh filename="package://mycobot_description/meshes/gripper/right_finger_link.STL" />
            </geometry>
        </collision>
    </link>
    <!-- define right_inner_knuckle_finger_joint -->
    <joint name="right_inner_knuckle_finger_joint" type="continuous">
        <origin rpy="0 0 -1.2508" xyz="0.026746 0.015702 0.005" />
        <parent link="right_inner_knuckle_link" />
        <child link="right_finger_link" />
        <axis xyz="0 0 1" />
        <mimic joint="left_outer_base_knuckle_joint" multiplier="1" offset="0" />
    </joint>
    <!-- define right_outer_knuckle_link -->
    <link name="right_outer_knuckle_link">
        <inertial>
            <origin rpy="0 0 0" xyz="0.0026671 -0.003562 0.0056204" />
            <mass value="0.0030687" />
            <inertia ixx="5.4543E-07" ixy="-1.7697E-09" ixz="2.7991E-09" iyy="3.3169E-07" iyz="1.4798E-07" izz="2.2484E-07" />
        </inertial>
        <visual>
            <origin rpy="0 0 0" xyz="0 0 0" />
            <geometry>
                <mesh filename="package://mycobot_description/meshes/gripper/right_outer_knuckle_link.STL" />
            </geometry>
            <material name="">
                <color rgba="0.79216 0.81961 0.93333 1" />
            </material>
        </visual>
        <collision>
            <origin rpy="0 0 0" xyz="0 0 0" />
            <geometry>
                <mesh filename="package://mycobot_description/meshes/gripper/right_outer_knuckle_link.STL" />
            </geometry>
        </collision>
    </link>
    <!-- define right_outer_base_knuckle_joint -->
    <joint name="right_outer_base_knuckle_joint" type="continuous">
        <origin rpy="-1.6401 0 -1.5708" xyz="0.01225 -0.0088 -0.00252" />
        <parent link="gripper_base_link" />
        <child link="right_outer_knuckle_link" />
        <axis xyz="1 0 0" />
        <mimic joint="left_outer_base_knuckle_joint" multiplier="-1" offset="0" />
    </joint>
    <material name="camera_aluminum">
        <color rgba="0.5 0.5 0.5 1" />
    </material>
    <!-- camera body, with origin at bottom screw mount -->
    <joint name="camera_joint" type="fixed">
        <origin rpy="0 0 0" xyz="-0.5 0 0.5" />
        <parent link="world" />
        <child link="camera_bottom_screw_frame" />
    </joint>
    <link name="camera_bottom_screw_frame" />
    <joint name="camera_link_joint" type="fixed">
        <origin rpy="0 0 0" xyz="0 0.0175 0.0125" />
        <parent link="camera_bottom_screw_frame" />
        <child link="camera_link" />
    </joint>
    <link name="camera_link">
        <visual>
            <!--<origin xyz="${d435_cam_mount_from_center_offset} ${-d435_cam_depth_py} 0" rpy="${M_PI/2} 0 ${M_PI/2}"/>-->
            <origin rpy="1.5707963267948966 0 1.5707963267948966" xyz="0 -0.0175 0" />
            <geometry>
                <!-- <box size="${d435_cam_width} ${d435_cam_height} ${d435_cam_depth}"/> -->
                <mesh filename="package://mycobot_description/meshes/camera/d435.dae" />
            </geometry>
            <material name="camera_aluminum" />
        </visual>
        <collision>
            <origin rpy="0 0 0" xyz="0 -0.0175 0" />
            <geometry>
                <box size="0.02505 0.09 0.025" />
            </geometry>
        </collision>
        <inertial>
            <!-- The following are not reliable values, and should not be used for modeling -->
            <mass value="0.564" />
            <origin xyz="0 0 0" rpy="0 0 0" />
            <inertia ixx="0.003881243" ixy="0.0" ixz="0.0" iyy="0.000498940" iyz="0.0" izz="0.003879257" />
        </inertial>
    </link>
    <!-- camera depth joints and links -->
    <joint name="camera_depth_joint" type="fixed">
        <origin rpy="0 0 0" xyz="0 0 0" />
        <parent link="camera_link" />
        <child link="camera_depth_frame" />
    </joint>
    <link name="camera_depth_frame" />
    <joint name="camera_depth_optical_joint" type="fixed">
        <origin rpy="-1.5707963267948966 0 -1.5707963267948966" xyz="0 0 0" />
        <parent link="camera_depth_frame" />
        <child link="camera_depth_optical_frame" />
    </joint>
    <link name="camera_depth_optical_frame" />
    <!-- camera left IR joints and links -->
    <joint name="camera_left_ir_joint" type="fixed">
        <origin rpy="0 0 0" xyz="0 0.0 0" />
        <parent link="camera_depth_frame" />
        <child link="camera_left_ir_frame" />
    </joint>
    <link name="camera_left_ir_frame" />
    <joint name="camera_left_ir_optical_joint" type="fixed">
        <origin rpy="-1.5707963267948966 0 -1.5707963267948966" xyz="0 0 0" />
        <parent link="camera_left_ir_frame" />
        <child link="camera_left_ir_optical_frame" />
    </joint>
    <link name="camera_left_ir_optical_frame" />
    <!-- camera right IR joints and links -->
    <joint name="camera_right_ir_joint" type="fixed">
        <origin rpy="0 0 0" xyz="0 -0.05 0" />
        <parent link="camera_depth_frame" />
        <child link="camera_right_ir_frame" />
    </joint>
    <link name="camera_right_ir_frame" />
    <joint name="camera_right_ir_optical_joint" type="fixed">
        <origin rpy="-1.5707963267948966 0 -1.5707963267948966" xyz="0 0 0" />
        <parent link="camera_right_ir_frame" />
        <child link="camera_right_ir_optical_frame" />
    </joint>
    <link name="camera_right_ir_optical_frame" />
    <!-- camera color joints and links -->
    <joint name="camera_color_joint" type="fixed">
        <origin rpy="0 0 0" xyz="0 0.015 0" />
        <parent link="camera_depth_frame" />
        <child link="camera_color_frame" />
    </joint>
    <link name="camera_color_frame" />
    <joint name="camera_color_optical_joint" type="fixed">
        <origin rpy="-1.5707963267948966 0 -1.5707963267948966" xyz="0 0 0" />
        <parent link="camera_color_frame" />
        <child link="camera_color_optical_frame" />
    </joint>
    <link name="camera_color_optical_frame" />
    <gazebo reference="camera_link">
        <self_collide>0</self_collide>
        <enable_wind>0</enable_wind>
        <kinematic>0</kinematic>
        <gravity>1</gravity>
        <!--<mu>1</mu>-->
        <mu2>1</mu2>
        <fdir1>0 0 0</fdir1>
        <!--<slip1>0</slip1>
      <slip2>0</slip2>-->
        <kp>1e+13</kp>
        <kd>1</kd>
        <!--<max_vel>0.01</max_vel>
      <min_depth>0</min_depth>-->
        <sensor name="cameracolor" type="camera">
            <camera name="camera">
                <horizontal_fov>1.2112585008840648</horizontal_fov>
                <image>
                    <width>640</width>
                    <height>480</height>
                    <format>RGB_INT8</format>
                </image>
                <clip>
                    <near>0.1</near>
                    <far>100</far>
                </clip>
                <noise>
                    <type>gaussian</type>
                    <mean>0.0</mean>
                    <stddev>0.007</stddev>
                </noise>
            </camera>
            <always_on>1</always_on>
            <update_rate>30</update_rate>
            <visualize>1</visualize>
        </sensor>
        <sensor name="cameraired1" type="camera">
            <camera name="camera">
                <horizontal_fov>1.4870205226991688</horizontal_fov>
                <image>
                    <width>1280</width>
                    <height>720</height>
                    <format>L_INT8</format>
                </image>
                <clip>
                    <near>0.1</near>
                    <far>100</far>
                </clip>
                <noise>
                    <type>gaussian</type>
                    <mean>0.0</mean>
                    <stddev>0.05</stddev>
                </noise>
            </camera>
            <always_on>1</always_on>
            <update_rate>90</update_rate>
            <visualize>0</visualize>
        </sensor>
        <sensor name="cameraired2" type="camera">
            <camera name="camera">
                <horizontal_fov>1.4870205226991688</horizontal_fov>
                <image>
                    <width>1280</width>
                    <height>720</height>
                    <format>L_INT8</format>
                </image>
                <clip>
                    <near>0.1</near>
                    <far>100</far>
                </clip>
                <noise>
                    <type>gaussian</type>
                    <mean>0.0</mean>
                    <stddev>0.05</stddev>
                </noise>
            </camera>
            <always_on>1</always_on>
            <update_rate>90</update_rate>
            <visualize>0</visualize>
        </sensor>
        <sensor name="cameradepth" type="depth">
            <camera name="camera">
                <horizontal_fov>1.4870205226991688</horizontal_fov>
                <image>
                    <width>1280</width>
                    <height>720</height>
                </image>
                <clip>
                    <near>0.1</near>
                    <far>100</far>
                </clip>
                <noise>
                    <type>gaussian</type>
                    <mean>0.0</mean>
                    <stddev>0.100</stddev>
                </noise>
            </camera>
            <always_on>1</always_on>
            <update_rate>90</update_rate>
            <visualize>0</visualize>
        </sensor>
    </gazebo>
    <gazebo>
        <plugin filename="librealsense_gazebo_plugin.so" name="camera">
            <prefix>camera</prefix>
            <depthUpdateRate>30.0</depthUpdateRate>
            <colorUpdateRate>30.0</colorUpdateRate>
            <infraredUpdateRate>30.0</infraredUpdateRate>
            <depthTopicName>depth/image_raw</depthTopicName>
            <depthCameraInfoTopicName>depth/camera_info</depthCameraInfoTopicName>
            <colorTopicName>color/image_raw</colorTopicName>
            <colorCameraInfoTopicName>color/camera_info</colorCameraInfoTopicName>
            <infrared1TopicName>infra1/image_raw</infrared1TopicName>
            <infrared1CameraInfoTopicName>infra1/camera_info</infrared1CameraInfoTopicName>
            <infrared2TopicName>infra2/image_raw</infrared2TopicName>
            <infrared2CameraInfoTopicName>infra2/camera_info</infrared2CameraInfoTopicName>
            <colorOpticalframeName>camera_color_optical_frame</colorOpticalframeName>
            <depthOpticalframeName>camera_depth_optical_frame</depthOpticalframeName>
            <infrared1OpticalframeName>camera_left_ir_optical_frame</infrared1OpticalframeName>
            <infrared2OpticalframeName>camera_right_ir_optical_frame</infrared2OpticalframeName>
            <rangeMinDepth>0.2</rangeMinDepth>
            <rangeMaxDepth>10.0</rangeMaxDepth>
            <pointCloud>True</pointCloud>
            <pointCloudTopicName>depth/color/points</pointCloudTopicName>
            <pointCloudCutoff>0.25</pointCloudCutoff>
            <pointCloudCutoffMax>9.0</pointCloudCutoffMax>
        </plugin>
    </gazebo>
    <transmission name="trans_left_inner_base_knuckle_joint">
        <type>transmission_interface/SimpleTransmission</type>
        <joint name="left_inner_base_knuckle_joint">
            <hardwareInterface>hardware_interface/EffortJointInterface</hardwareInterface>
        </joint>
        <actuator name="left_inner_base_knuckle_joint_motor">
            <hardwareInterface>hardware_interface/EffortJointInterface</hardwareInterface>
            <mechanicalReduction>1</mechanicalReduction>
        </actuator>
    </transmission>
    <transmission name="trans_left_inner_knuckle_finger_joint">
        <type>transmission_interface/SimpleTransmission</type>
        <joint name="left_inner_knuckle_finger_joint">
            <hardwareInterface>hardware_interface/EffortJointInterface</hardwareInterface>
        </joint>
        <actuator name="left_inner_knuckle_finger_joint_motor">
            <hardwareInterface>hardware_interface/EffortJointInterface</hardwareInterface>
            <mechanicalReduction>1</mechanicalReduction>
        </actuator>
    </transmission>
    <transmission name="trans_right_inner_base_knuckle_joint">
        <type>transmission_interface/SimpleTransmission</type>
        <joint name="right_inner_base_knuckle_joint">
            <hardwareInterface>hardware_interface/EffortJointInterface</hardwareInterface>
        </joint>
        <actuator name="right_inner_base_knuckle_joint_motor">
            <hardwareInterface>hardware_interface/EffortJointInterface</hardwareInterface>
            <mechanicalReduction>1</mechanicalReduction>
        </actuator>
    </transmission>
    <transmission name="trans_right_inner_knuckle_finger_joint">
        <type>transmission_interface/SimpleTransmission</type>
        <joint name="right_inner_knuckle_finger_joint">
            <hardwareInterface>hardware_interface/EffortJointInterface</hardwareInterface>
        </joint>
        <actuator name="right_inner_knuckle_finger_joint_motor">
            <hardwareInterface>hardware_interface/EffortJointInterface</hardwareInterface>
            <mechanicalReduction>1</mechanicalReduction>
        </actuator>
    </transmission>
    <transmission name="trans_right_outer_base_knuckle_joint">
        <type>transmission_interface/SimpleTransmission</type>
        <joint name="right_outer_base_knuckle_joint">
            <hardwareInterface>hardware_interface/EffortJointInterface</hardwareInterface>
        </joint>
        <actuator name="right_outer_base_knuckle_joint_motor">
            <hardwareInterface>hardware_interface/EffortJointInterface</hardwareInterface>
            <mechanicalReduction>1</mechanicalReduction>
        </actuator>
    </transmission>
</robot>

